Workbook

Sheet Project Information

Sheet Methodology
A1: Methodology & Quality Controls
A3: Function | B3: Purpose
A4: PV | B4: Present value
A5: NPV | B5: Periodic cash flows
A6: XNPV | B6: Irregular cash flows
A7: PMT | B7: Loan payment
A8: IPMT / PPMT | B8: Interest / principal
A9: CUMIPMT / CUMPRINC | B9: Cumulative components
A10: RATE | B10: Implied rate
A11: NPER | B11: Loan term
A12: IRR | B12: Periodic return
A13: XIRR | B13: Irregular-date return
A14: MIRR | B14: Separate finance/reinvestment rates
A17: Quality Checks
A18: Negative = cash paid; positive = cash received.
A19: XNPV/XIRR dates are chronological and use the earliest date as the base.
A20: Loan schedule reconciles beginning balance, EMI, interest, principal and ending balance.
A21: NPV timing variants distinguish end-, beginning- and middle-of-period cash flows.
A22: IRR guess sensitivity is included to expose multiple-root behavior.
A23: Independent numerical calculations were used to validate major outputs.

Sheet Annuity
A1: Annuity
A3: Price | B3: 32000 | D3: Price | E3: 32000
A4: Interest Rate | B4: 0.13 | D4: Interest Rate | E4: 0.13
A5: No. of payments | B5: 8 | D5: No. of payments | E5: 8
A6: Payment | B6: -6000 | D6: Payment | E6: -6000
A7: Payments at end of the year | D7: Payments at Beginning of the year
A8: PV | B8: =PV(B4,B5,B6,,0) -> 28792.622 | D8: PV | E8: =PV(E4,E5,E6,,1) -> 32535.663
A10: Interpretation | D10: Interpretation
A11: Lower PV | D11: Higher PV

Sheet Loan & EMI
A1: Loan, EMI & Repayment Schedule
A3: EMI Scenarios
A4: 25-year Home Loan | D4: 8-month Loan
A5: Rate per annum | B5: 0.12 | D5: Rate per annum | E5: 0.16
A6: Rate per month | B6: =B5/12 -> 0.01 | D6: Rate per month | E6: =E5/12 -> 0.013333333
A7: Term | B7: 25 | D7: Term | E7: 8
A8: No. of monthly payments | B8: =B7*12 -> 300 | D8: Loan Amount (PV) | E8: -100000
A9: Loan Amount (PV) | B9: -5000000 | D9: FV | E9: 0
A10: FV | B10: 0 | D10: Type | E10: 0
A11: Type | B11: 1 | D11: EMI | E11: =PMT(E6,E7,E8,E9,E10) -> 13261.587
A12: EMI | B12: =PMT(B6,B8,B9,B10,B11) -> 52139.809
A14: Amortization
A15: Rate per month | B15: 0.013
A16: No. of monthly payment | B16: 8
A17: Loan Amount (PV) | B17: 100000
A18: FV | B18: 0
A19: Type | B19: 0
A20: EMI | B20: =PMT(B15,B16,B17,B18,B19) -> -13242.267
A22: Month | B22: Beginning Balance | C22: EMI | D22: Interest | E22: Principal | F22: Ending Balance
A23: 1 | B23: =B17 -> 100000 | C23: =-$B$20 -> 13242.267 | D23: =-IPMT($B$15,A23,$B$16,$B$17,$B$18,$B$19) -> 1300 | E23: =-PPMT($B$15,A23,$B$16,$B$17,$B$18,$B$19) -> 11942.267 | F23: =B23-E23 -> 88057.733
A24: =A23+1 -> 2 | B24: =F23 -> 88057.733 | C24: =-$B$20 -> 13242.267 | D24: =-IPMT($B$15,A24,$B$16,$B$17,$B$18,$B$19) -> 1144.7505 | E24: =-PPMT($B$15,A24,$B$16,$B$17,$B$18,$B$19) -> 12097.517 | F24: =B24-E24 -> 75960.216
A25: =A24+1 -> 3 | B25: =F24 -> 75960.216 | C25: =-$B$20 -> 13242.267 | D25: =-IPMT($B$15,A25,$B$16,$B$17,$B$18,$B$19) -> 987.48281 | E25: =-PPMT($B$15,A25,$B$16,$B$17,$B$18,$B$19) -> 12254.784 | F25: =B25-E25 -> 63705.432
A26: =A25+1 -> 4 | B26: =F25 -> 63705.432 | C26: =-$B$20 -> 13242.267 | D26: =-IPMT($B$15,A26,$B$16,$B$17,$B$18,$B$19) -> 828.17061 | E26: =-PPMT($B$15,A26,$B$16,$B$17,$B$18,$B$19) -> 12414.097 | F26: =B26-E26 -> 51291.335
A27: =A26+1 -> 5 | B27: =F26 -> 51291.335 | C27: =-$B$20 -> 13242.267 | D27: =-IPMT($B$15,A27,$B$16,$B$17,$B$18,$B$19) -> 666.78736 | E27: =-PPMT($B$15,A27,$B$16,$B$17,$B$18,$B$19) -> 12575.48 | F27: =B27-E27 -> 38715.855
A28: =A27+1 -> 6 | B28: =F27 -> 38715.855 | C28: =-$B$20 -> 13242.267 | D28: =-IPMT($B$15,A28,$B$16,$B$17,$B$18,$B$19) -> 503.30612 | E28: =-PPMT($B$15,A28,$B$16,$B$17,$B$18,$B$19) -> 12738.961 | F28: =B28-E28 -> 25976.894
A29: =A28+1 -> 7 | B29: =F28 -> 25976.894 | C29: =-$B$20 -> 13242.267 | D29: =-IPMT($B$15,A29,$B$16,$B$17,$B$18,$B$19) -> 337.69963 | E29: =-PPMT($B$15,A29,$B$16,$B$17,$B$18,$B$19) -> 12904.568 | F29: =B29-E29 -> 13072.327
A30: =A29+1 -> 8 | B30: =F29 -> 13072.327 | C30: =-$B$20 -> 13242.267 | D30: =-IPMT($B$15,A30,$B$16,$B$17,$B$18,$B$19) -> 169.94025 | E30: =-PPMT($B$15,A30,$B$16,$B$17,$B$18,$B$19) -> 13072.327 | F30: =B30-E30 -> 0
A32: Cumulative Months 2–3
A33: Interest paid between 2nd and 3rd months
A34: =-CUMIPMT(B15,B16,B17,2,3,B19) -> 2132.2333
A35: =D24+D25 -> 2132.2333
A36: Principal paid between 2nd and 3rd months
A37: =-CUMPRINC(B15,B16,B17,2,3,B19) -> 24352.301
A38: =E24+E25 -> 24352.301
A40: RATE & NPER
A41: RATE
A42: Loan Amount | B42: 100000
A43: No.of monthly payment | B43: 15
A44: EMI | B44: -12000
A45: Interest | B45: =RATE(B43,B44,B42,,0,) -> 0.08441798
...

Sheet Investment Analysis
A1: Decision on Investments
A3: Interest Rate | B3: 0.2
B4: Cash Flow
A5: Time | B5: Investement 1 | C5: Investement 2
A6: 1 | B6: -10000 | C6: -5000
A7: 2 | B7: 25000 | C7: 20000
A8: 3 | B8: -7000 | C8: -8000
A9: Total | B9: =SUM(B6:B8) -> 8000 | C9: =SUM(C6:C8) -> 7000
A11: Timing | B11: Investment 1 | C11: Investment 2 | D11: Preferred
A12: NPV (End Year) | B12: =NPV(B3,B6:B8) -> 4976.8519 | C12: =NPV(B3,C6:C8) -> 5092.5926 | D12: Investment 2
A13: NPV (Beginning Year) | B13: =B6+NPV(B3,B7:B8) -> 5972.2222 | C13: =C6+NPV(B3,C7:C8) -> 6111.1111 | D13: Investment 2
A14: NPV (Middle Year) | B14: =SQRT(1+B3)*B12 -> 5451.868 | C14: =SQRT(1+B3)*C12 -> 5578.6557 | D14: Investment 2

Sheet XNPV
A1: XNPV — Irregular Cash Flows
A3: Interest Rate | B3: 0.2 | D3: Interest Rate | E3: 0.2
A4: Date | B4: Cash Flow | D4: Date | E4: Cash Flow
A5: 42536 | B5: 5000 | D5: 42078 | E5: 0
A6: 42657 | B6: 5143 | D6: 42536 | E6: 5000
A7: 42855 | B7: 8838 | D7: 42657 | E7: 5143
A8: 42684 | B8: -4893 | D8: 42855 | E8: 8838
A9: 42629 | B9: -2134 | D9: 42684 | E9: -4893
A10: 42843 | B10: 8047 | D10: 42629 | E10: -2134
A11: 42609 | B11: 3908 | D11: 42843 | E11: 8047
A12: 42568 | B12: -4007 | D12: 42609 | E12: 3908
D13: 42568 | E13: -4007
A14: NPV | B14: =XNPV(B3,B5:B12,A5:A12) -> 17523.655 | D14: NPV | E14: =XNPV(E3,E5:E13,D5:D13) -> 13940.183

Sheet NPV - DIFFERENT RATE
A1: NPV WITH DIFFERENT RATE
A3: Cash Flow | B3: Interest Rate | C3: NPV
A4: 10000 | B4: 0.08 | C4: =NPV(B4,$A$4:$A$7) -> -304.94919
A5: -5000 | B5: 0.085 | C5: =NPV(B5,$A$4:$A$7) -> -242.25684
A6: -8500 | B6: 0.09 | C6: =NPV(B6,$A$4:$A$7) -> -180.7972
A7: 2000 | B7: 0.095 | C7: =NPV(B7,$A$4:$A$7) -> -120.54389
B8: 0.1 | C8: =NPV(B8,$A$4:$A$7) -> -61.471211
B9: 0.1053 | C9: =NPV(B9,$A$4:$A$7) -> -0.11523532
B10: 0.11 | C10: =NPV(B10,$A$4:$A$7) -> 53.23205
B11: 0.115 | C11: =NPV(B11,$A$4:$A$7) -> 108.911
B12: 0.12 | C12: =NPV(B12,$A$4:$A$7) -> 163.50609

Sheet IRR & XIRR
A1: IRR, XIRR & Multiple-IRR Diagnostics
A3: IRR
A5: Cash Flows | C5: Cash Flows | D5: Guess | E5: IRR
A6: 10000 | C6: 10000 | E6: =IRR(C6:C9) -> 0.10531006
A7: -5000 | C7: -5000 | D7: 0.05 | E7: =IRR($C$6:$C$9,D7) -> 0.10531006
A8: -8500 | C8: -8500 | D8: 0.15 | E8: =IRR($C$6:$C$9,D8) -> 0.10531006
A9: 2000 | C9: 2000 | D9: 0.2 | E9: =IRR($C$6:$C$9,D9) -> 0.10531006
D10: 0.25 | E10: =IRR($C$6:$C$9,D10) -> 0.10531006
A11: IRR | D11: 0.3 | E11: =IRR($C$6:$C$9,D11) -> 0.10531006
A12: =IRR(A6:A9) -> 0.10531006 | D12: 0.35 | E12: =IRR($C$6:$C$9,D12) -> 0.10531006
D13: 0.4 | E13: =IRR($C$6:$C$9,D13) -> 0.10531006
D14: 0.45 | E14: =IRR($C$6:$C$9,D14) -> 0.10531006
D15: 0.5 | E15: =IRR($C$6:$C$9,D15) -> 0.10531006
D16: 0.55 | E16: =IRR($C$6:$C$9,D16) -> 0.10531006
A18: Multiple-IRR Example — Guess Sensitivity
A19: Cash Flows | B19: Guess | C19: IRR
A20: -20000 | C20: =IRR(A20:A23) -> -0.095909414
A21: 82000 | B21: 0.15 | C21: =IRR($A$20:$A$23,B21) -> -0.095909414
A22: -60000 | B22: 0.2 | C22: =IRR($A$20:$A$23,B22) -> -0.095909414
A23: 2000 | B23: 0.25 | C23: =IRR($A$20:$A$23,B23) -> -0.095909414
B24: 0.3 | C24: =IRR($A$20:$A$23,B24) -> -0.095909414
B25: 0.35 | C25: =IRR($A$20:$A$23,B25) -> -0.095909414
B26: 0.4 | C26: =IRR($A$20:$A$23,B26) -> -0.095909414
B27: 0.45 | C27: =IRR($A$20:$A$23,B27) -> 2.1609169
B28: 0.5 | C28: =IRR($A$20:$A$23,B28) -> 2.1609169
B29: 0.55 | C29: =IRR($A$20:$A$23,B29) -> 2.1609169
B30: 0.6 | C30: =IRR($A$20:$A$23,B30) -> 2.1609169
A32: Cash Flows | B32: Guess | C32: IRR
A33: 10000 | C33: =IRR($A$33:$A$36,B33) -> #NUM!
A34: -5000 | B34: 0.05 | C34: =IRR($A$33:$A$36,B34) -> #NUM!
A35: 8500 | B35: 0.15 | C35: =IRR($A$33:$A$36,B35) -> #NUM!
A36: 2000 | B36: 0.2 | C36: =IRR($A$33:$A$36,B36) -> #NUM!
B37: 0.25 | C37: =IRR($A$33:$A$36,B37) -> #NUM!
B38: 0.3 | C38: =IRR($A$33:$A$36,B38) -> #NUM!
B39: 0.35 | C39: =IRR($A$33:$A$36,B39) -> #NUM!
B40: 0.4 | C40: =IRR($A$33:$A$36,B40) -> #NUM!
B41: 0.45 | C41: =IRR($A$33:$A$36,B41) -> #NUM!
B42: 0.5 | C42: =IRR($A$33:$A$36,B42) -> #NUM!
B43: 0.55 | C43: =IRR($A$33:$A$36,B43) -> #NUM!
A45: XIRR — Irregular Dates
...

Sheet MIRR
A1: Modified IRR (MIRR)
A3: Year | B3: Cash Flow | D3: Finance rate | E3: 0.1
A4: 0 | B4: -1.6 | D4: Reinvestment Rate | E4: 0.12
A5: 1 | B5: 10
A6: 2 | B6: -10
A8: Discount | B8: NPV
A9: 0.1 | B9: =NPV(A9,$B$4:$B$6) -> -0.70323065
A10: 0.25 | B10: =NPV(A10,$B$4:$B$6) -> 0
A11: 1.1 | B11: =NPV(A11,$B$4:$B$6) -> 0.42587194
A12: 4 | B12: =NPV(A12,$B$4:$B$6) -> -2.220446e-17
A13: 5 | B13: =NPV(A13,$B$4:$B$6) -> -0.035185185
A15: MIRR | B15: =MIRR(B4:B6,E3,E4) -> 0.065546217

Sheet Executive Summary
A1: Executive Summary
A3: Key Results
A4: Metric | B4: Result | C4: Interpretation
A5: PV — End Year | B5: =Annuity!B8 -> 28792.622 | C5: Lower PV
A6: PV — Beginning Year | B6: =Annuity!E8 -> 32535.663 | C6: Higher PV
A7: 25-year Home Loan EMI | B7: ='Loan & EMI'!B12 -> 52139.809 | C7: Monthly payment
A8: 8-month Loan EMI | B8: ='Loan & EMI'!E11 -> 13261.587 | C8: Monthly payment
A9: RATE — Monthly | B9: ='Loan & EMI'!B45 -> 0.08441798 | C9: Implied rate
A10: NPER — Months | B10: ='Loan & EMI'!B51 -> 11.526705 | C10: Repayment periods
A11: Investment 1 NPV | B11: ='Investment Analysis'!B13 -> 5972.2222 | C11: 20% discount
A12: Investment 2 NPV | B12: ='Investment Analysis'!C13 -> 6111.1111 | C12: Preferred
A13: XNPV | B13: =XNPV!B14 -> 17523.655 | C13: 20% discount
A14: MIRR | B14: =MIRR!B15 -> 0.065546217 | C14: 10% / 12% rates
A17: Key Insights
A18: • Payment timing changes present value; earlier payments have a higher PV.
A19: • Loan interest declines and principal repayment increases as the balance falls.
A20: • Investment 2 has the higher NPV under the supplied 20% discount rate.
A21: • XNPV/XIRR are appropriate for irregularly dated cash flows.
A22: • Multiple IRRs can occur after multiple cash-flow sign changes; IRR should be interpreted with caution.
A23: • MIRR separates finance and reinvestment assumptions.
